<?xml version="1.0" encoding="utf-8"?>
<mujoco>
	<option timestep="0.02"></option>
	<size njmax="3000" nconmax="1000"></size>
	<default>
		<joint armature="1" damping="1" limited="true"></joint>
		<geom condim="3" density="5.0" friction="0.75 0.01 0.01" margin="0.01" rgba="1 0 0 1"></geom>
		<motor ctrllimited="true" ctrlrange="-1.0 1.0" gear="50"></motor>
		<site size="0.2" type="sphere" rgba="0 0 1 0"></site>
	</default>
	<worldbody>
		<geom name="floor" size="3.5 3.5 0.1" type="plane" condim="3" rgba="1 1 1 1" material="MatPlane"></geom>
		<body name="robot" pos="0.0 0.0 0.75" quat="0.2533820055482905 0.0 0.0 0.9673663004593069">
			<site name="robot" rgba="1 0 0 .01"></site>
			<camera name="vision" pos=".125 0 .2" xyaxes="0 -1 0 .4 0 1" fovy="100"></camera>
			<camera name="track" mode="track" pos="-0.9804528532408373 1.7431902370573045 2" xyaxes="-0.8715951185286522 -0.49022642662041865 0 0.49022642662041865 -0.8715951185286522 1"></camera>
			<geom name="robot" pos="0 0 0" size="0.06" type="sphere"></geom>
			<joint armature="0" damping="0" limited="false" margin="0.01" name="robot" pos="0 0 0" type="free"></joint>
			<body name="front_left_leg" pos="0 0 0">
				<geom fromto="0.0 0.0 0.0 0.05 0.05 0.0" name="aux_1_geom" size="0.02" type="capsule"></geom>
				<body name="aux_1" pos="0.05 0.05 0">
					<joint axis="0 0 1" name="hip_1" pos="0.0 0.0 0.0" range="-30 30" type="hinge"></joint>
					<geom fromto="0.0 0.0 0.0 0.05 0.05 0.0" name="front_left_leg_geom" size="0.02" type="capsule"></geom>
					<body pos="0.05 0.05 0">
						<joint axis="-1 1 0" name="ankle_1" pos="0.0 0.0 0.0" range="30 70" type="hinge"></joint>
						<geom fromto="0.0 0.0 0.0 0.1 0.1 0.0" name="front_left_ankle_geom" size="0.02" type="capsule"></geom>
						<site name="ankle_1a" pos="0 0 0"></site>
						<site name="ankle_1b" pos="0.1 0.1 0.0"></site>
					</body>
				</body>
			</body>
			<body name="front_right_leg" pos="0 0 0">
				<geom fromto="0.0 0.0 0.0 -0.05 0.05 0.0" name="aux_2_geom" size="0.02" type="capsule"></geom>
				<body name="aux_2" pos="-0.05 0.05 0">
					<joint axis="0 0 1" name="hip_2" pos="0.0 0.0 0.0" range="-30 30" type="hinge"></joint>
					<geom fromto="0.0 0.0 0.0 -0.05 0.05 0.0" name="front_right_leg_geom" size="0.02" type="capsule"></geom>
					<body pos="-0.05 0.05 0">
						<joint axis="1 1 0" name="ankle_2" pos="0.0 0.0 0.0" range="-70 -30" type="hinge"></joint>
						<geom fromto="0.0 0.0 0.0 -0.1 0.1 0.0" name="front_right_ankle_geom" size="0.02" type="capsule"></geom>
						<site name="ankle_2a" pos="0 0 0"></site>
						<site name="ankle_2b" pos="-0.1 0.1 0.0"></site>
					</body>
				</body>
			</body>
			<body name="back_left_leg" pos="0 0 0">
				<geom fromto="0.0 0.0 0.0 -0.05 -0.05 0.0" name="aux_3_geom" size="0.02" type="capsule"></geom>
				<body name="aux_3" pos="-0.05 -0.05 0">
					<joint axis="0 0 1" name="hip_3" pos="0.0 0.0 0.0" range="-30 30" type="hinge"></joint>
					<geom fromto="0.0 0.0 0.0 -0.05 -0.05 0.0" name="back_left_leg_geom" size="0.02" type="capsule"></geom>
					<body pos="-0.05 -0.05 0">
						<joint axis="-1 1 0" name="ankle_3" pos="0.0 0.0 0.0" range="-70 -30" type="hinge"></joint>
						<geom fromto="0.0 0.0 0.0 -0.1 -0.1 0.0" name="back_left_ankle_geom" size="0.02" type="capsule"></geom>
						<site name="ankle_3a" pos="0 0 0"></site>
						<site name="ankle_3b" pos="-0.1 -0.1 0.0"></site>
					</body>
				</body>
			</body>
			<body name="back_right_leg" pos="0 0 0">
				<geom fromto="0.0 0.0 0.0 0.05 -0.05 0.0" name="aux_4_geom" size="0.02" type="capsule"></geom>
				<body name="aux_4" pos="0.05 -0.05 0">
					<joint axis="0 0 1" name="hip_4" pos="0.0 0.0 0.0" range="-30 30" type="hinge"></joint>
					<geom fromto="0.0 0.0 0.0 0.05 -0.05 0.0" name="back_right_leg_geom" size="0.02" type="capsule"></geom>
					<body pos="0.05 -0.05 0">
						<joint axis="1 1 0" name="ankle_4" pos="0.0 0.0 0.0" range="30 70" type="hinge"></joint>
						<geom fromto="0.0 0.0 0.0 0.1 -0.1 0.0" name="back_right_ankle_geom" size="0.02" type="capsule"></geom>
						<site name="ankle_4a" pos="0 0 0"></site>
						<site name="ankle_4b" pos="0.1 -0.1 0.0"></site>
					</body>
				</body>
			</body>
		</body> 
		<body name="goal" pos="0. 0. 0." quat="1. 0. 0. 0.">
			<joint type="slide" axis="1 0 0" name="goal_x" damping="0" limited="false"/>
            <joint type="slide" axis="0 1 0" name="goal_y" damping="0" limited="false"/>
			<geom name="goal" type="sphere" size="0.5" rgba="0.0 1.0 0.0 0.25" group="0" contype="0" conaffinity="0"></geom>
		</body>
		<body name="hazard0" pos="0. 0. 0." quat="1. 0. 0. 0.">
			<joint type="slide" axis="1 0 0" name="hazard0_x" damping="0" limited="false"/>
            <joint type="slide" axis="0 1 0" name="hazard0_y" damping="0" limited="false"/>
			<geom name="hazard0" type="sphere" size="0.3 " rgba="0.0 0.0 1.0 0.25" group="3" contype="0" conaffinity="0"></geom>
		</body>
		<light cutoff="100" diffuse="1 1 1" dir="0 0 -1" directional="true" exponent="1" pos="0 0 0.5" specular="0 0 0" castshadow="false"></light>
		<camera name="fixednear" pos="0 -2 2" zaxis="0 -1 1"></camera>
		<camera name="fixedfar" pos="0 -5 5" zaxis="0 -1 1"></camera>
	</worldbody>
	<sensor>
		<accelerometer site="robot" name="accelerometer"></accelerometer>
		<velocimeter site="robot" name="velocimeter"></velocimeter>
		<gyro site="robot" name="gyro"></gyro>
		<magnetometer site="robot" name="magnetometer"></magnetometer>
		<subtreecom body="robot" name="subtreecom"></subtreecom>
		<subtreelinvel body="robot" name="subtreelinvel"></subtreelinvel>
		<subtreeangmom body="robot" name="subtreeangmom"></subtreeangmom>
	</sensor>
	<actuator>
        <motor name="hip_1" joint="hip_1"></motor>
		<motor name="ankle_1" joint="ankle_1"></motor>
		<motor name="hip_2" joint="hip_2"></motor>
		<motor name="ankle_2" joint="ankle_2"></motor>
		<motor name="hip_3" joint="hip_3"></motor>
		<motor name="ankle_3" joint="ankle_3"></motor>
		<motor name="hip_4" joint="hip_4"></motor>
		<motor name="ankle_4" joint="ankle_4"></motor>
	</actuator>
	<equality>
	</equality>
	<asset>
		<texture type="skybox" builtin="gradient" rgb1="0.527 0.582 0.906" rgb2="0.1 0.1 0.35" width="800" height="800" markrgb="1 1 1" mark="random" random="0.001"></texture>
		<texture name="texplane" builtin="checker" height="100" width="100" rgb1="0.7 0.7 0.7" rgb2="0.8 0.8 0.8" type="2d"></texture>
		<material name="MatPlane" reflectance="0.1" shininess="0.1" specular="0.1" texrepeat="10 10" texture="texplane"></material>
	</asset>
</mujoco>