<?xml version="1.0" encoding="utf-8"?>
<mujoco model="walker">
	<compiler angle="degree" coordinate="local" inertiafromgeom="true"></compiler>
	<size njmax="3000" nconmax="1000"></size>
	<default>
		<joint armature="1" damping="20" limited="true"></joint>
		<geom condim="3" density="50.0" friction="0.75 0.01 0.01" rgba="1 0 0  1" contype="0" conaffinity="0"></geom>
		<site size="0.05" type="sphere" rgba="0 0 1 0"></site>
	</default>
	<option timestep="0.02"></option>
	<worldbody>
		<geom name="floor" size="3.5 3.5 0.1" type="plane" conaffinity="1" condim="3" rgba="1 1 1 1" material="MatPlane"></geom>
		<body name="robot" pos="0.0 0.0 0.42" quat="1.0 0.0 0.0 0.0">
			<site name="robot" rgba="1 0 0 .1"></site>
			<camera name="vision" pos=".125 0 .2" xyaxes="0 -1 0 .4 0 1" fovy="100"></camera>
			<camera name="track" mode="track" pos="0.0 -2.0 2" xyaxes="1.0 -0.0 0 0.0 1.0 1"></camera>
			<joint armature="0" axis="1 0 0" damping="10" limited="false" name="robot_x" pos="0 0 0" stiffness="0" type="slide"></joint>
			<joint armature="0" axis="0 0 1" damping="1" limited="false" name="robot_z" pos="0 0 0" stiffness="0.1" type="hinge"></joint>
			<joint armature="0" axis="0 1 0" damping="10" limited="false" name="robot_y" pos="0 0 0" stiffness="0" type="slide"></joint>
			<geom fromto="0 0.1 0 0 -0.1 0" name="robot_geom" size="0.03" type="capsule"></geom>
			<body name="right_thigh" pos="0 0.1 0">
				<joint armature="0.01" axis="1 0 0" damping="5" name="right_hip_x" pos="0 0 0" range="-25 5" stiffness="10" type="hinge"></joint>
				<joint armature="0.01" axis="0 0 1" damping="5" name="right_hip_z" pos="0 0 0" range="-30 35" stiffness="10" type="hinge"></joint>
				<joint armature="0.01" axis="0 1 0" damping="5" name="right_hip_y" pos="0 0 0" range="-100 10" stiffness="10" type="hinge"></joint>
				<geom fromto="0 0 0 0 0 -0.2" name="right_thigh_geom" size="0.03" type="capsule"></geom>
				<body name="right_leg" pos="0 0 -0.3">
					<joint axis="0 -1 0" name="right_leg_joint" pos="0 0 0.1" range="-100 0" type="hinge"></joint>
					<geom fromto="0 0 0.1 0 0 -0.1" name="right_leg_geom" size="0.02" type="capsule"></geom>
					<body name="right_foot" pos="0.0 0.0 0.0">
						<joint axis="0 -1 0" name="right_foot_joint" pos="0.0 0.0 -0.1" range="-45 20" type="hinge"></joint>
						<geom friction="2.0" fromto="0.0 0.0 -0.1 0.05 0.0 -0.1" name="right_foot_geom" size="0.03" type="capsule"></geom>
						<geom type="sphere" pos="0.05 0.0 -0.1" size="0.02" contype="1" conaffinity="0"></geom>
						<site name="right_foot" pos="0.05 0 -0.1"></site>
					</body>
				</body>
			</body>
			<body name="left_thigh" pos="0 -0.1 0">
				<joint armature="0.01" axis="-1 0 0" damping="5" name="left_hip_x" pos="0 0 0" range="-25 5" stiffness="10" type="hinge"></joint>
				<joint armature="0.01" axis="0 0 -1" damping="5" name="left_hip_z" pos="0 0 0" range="-30 35" stiffness="10" type="hinge"></joint>
				<joint armature="0.01" axis="0 1 0" damping="5" name="left_hip_y" pos="0 0 0" range="-100 10" stiffness="10" type="hinge"></joint>
				<geom fromto="0 0 0 0 0 -0.2" name="left_thigh_geom" size="0.03" type="capsule"></geom>
				<body name="left_leg" pos="0 0 -0.3">
					<joint axis="0 -1 0" name="left_leg_joint" pos="0 0 0.1" range="-100 0" type="hinge"></joint>
					<geom fromto="0 0 0.1 0 0 -0.1" name="left_leg_geom" size="0.02" type="capsule"></geom>
					<body name="left_foot" pos="0.0 0.0 0.0">
						<joint axis="0 -1 0" name="left_foot_joint" pos="0.0 0.0 -0.1" range="-45 20" type="hinge"></joint>
						<geom friction="2.0" fromto="0.0 0.0 -0.1 0.05 0.0 -0.1" name="left_foot_geom" size="0.03" type="capsule"></geom>
						<geom type="sphere" pos="0.05 0.0 -0.1" size="0.02" contype="1" conaffinity="0"></geom>
						<site name="left_foot" pos="0.05 0 -0.1"></site>
					</body>
				</body>
			</body>
		</body>
		<body name="goal" pos="0.0 0.0 0.0" quat="1.0 0.0 0.0 0.0">
			<joint type="slide" axis="1 0 0" name="goal_x" damping="1" limited="false"></joint>
			<joint type="slide" axis="0 1 0" name="goal_y" damping="1" limited="false"></joint>
			<geom name="goal" type="sphere" size="0.5" rgba="0.0 1.0 0.0 0.25" group="0" contype="0" conaffinity="0"></geom>
		</body>
		<body name="hazard0" pos="0.0 0.0 0.02" quat="1.0 0.0 0.0 0.0">
			<joint type="slide" axis="1 0 0" name="hazard0_x" damping="1" limited="false"></joint>
			<joint type="slide" axis="0 1 0" name="hazard0_y" damping="1" limited="false"></joint>
			<geom name="hazard0" type="cylinder" size="0.3 0.01" rgba="0.0 0.0 1.0 0.25" group="3" contype="0" conaffinity="0"></geom>
		</body>
		<body name="hazard1" pos="0.0 0.0 0.02" quat="1.0 0.0 0.0 0.0">
			<joint type="slide" axis="1 0 0" name="hazard1_x" damping="1" limited="false"></joint>
			<joint type="slide" axis="0 1 0" name="hazard1_y" damping="1" limited="false"></joint>
			<geom name="hazard1" type="cylinder" size="0.3 0.01" rgba="0.0 0.0 1.0 0.25" group="3" contype="0" conaffinity="0"></geom>
		</body>
		<body name="hazard2" pos="0.0 0.0 0.02" quat="1.0 0.0 0.0 0.0">
			<joint type="slide" axis="1 0 0" name="hazard2_x" damping="1" limited="false"></joint>
			<joint type="slide" axis="0 1 0" name="hazard2_y" damping="1" limited="false"></joint>
			<geom name="hazard2" type="cylinder" size="0.3 0.01" rgba="0.0 0.0 1.0 0.25" group="3" contype="0" conaffinity="0"></geom>
		</body>
		<body name="hazard3" pos="0.0 0.0 0.02" quat="1.0 0.0 0.0 0.0">
			<joint type="slide" axis="1 0 0" name="hazard3_x" damping="1" limited="false"></joint>
			<joint type="slide" axis="0 1 0" name="hazard3_y" damping="1" limited="false"></joint>
			<geom name="hazard3" type="cylinder" size="0.3 0.01" rgba="0.0 0.0 1.0 0.25" group="3" contype="0" conaffinity="0"></geom>
		</body>
		<body name="hazard4" pos="0.0 0.0 0.02" quat="1.0 0.0 0.0 0.0">
			<joint type="slide" axis="1 0 0" name="hazard4_x" damping="1" limited="false"></joint>
			<joint type="slide" axis="0 1 0" name="hazard4_y" damping="1" limited="false"></joint>
			<geom name="hazard4" type="cylinder" size="0.3 0.01" rgba="0.0 0.0 1.0 0.25" group="3" contype="0" conaffinity="0"></geom>
		</body>
		<body name="hazard5" pos="0.0 0.0 0.02" quat="1.0 0.0 0.0 0.0">
			<joint type="slide" axis="1 0 0" name="hazard5_x" damping="1" limited="false"></joint>
			<joint type="slide" axis="0 1 0" name="hazard5_y" damping="1" limited="false"></joint>
			<geom name="hazard5" type="cylinder" size="0.3 0.01" rgba="0.0 0.0 1.0 0.25" group="3" contype="0" conaffinity="0"></geom>
		</body>
		<body name="hazard6" pos="0.0 0.0 0.02" quat="1.0 0.0 0.0 0.0">
			<joint type="slide" axis="1 0 0" name="hazard6_x" damping="1" limited="false"></joint>
			<joint type="slide" axis="0 1 0" name="hazard6_y" damping="1" limited="false"></joint>
			<geom name="hazard6" type="cylinder" size="0.3 0.01" rgba="0.0 0.0 1.0 0.25" group="3" contype="0" conaffinity="0"></geom>
		</body>
		<body name="hazard7" pos="0.0 0.0 0.02" quat="1.0 0.0 0.0 0.0">
			<joint type="slide" axis="1 0 0" name="hazard7_x" damping="1" limited="false"></joint>
			<joint type="slide" axis="0 1 0" name="hazard7_y" damping="1" limited="false"></joint>
			<geom name="hazard7" type="cylinder" size="0.3 0.01" rgba="0.0 0.0 1.0 0.25" group="3" contype="0" conaffinity="0"></geom>
		</body>
		<light cutoff="100" diffuse="1 1 1" dir="0 0 -1" directional="true" exponent="1" pos="0 0 0.5" specular="0 0 0" castshadow="false"></light>
		<camera name="fixednear" pos="0 -2 2" zaxis="0 -1 1"></camera>
		<camera name="fixedfar" pos="0 -5 5" zaxis="0 -1 1"></camera>
	</worldbody>
	<sensor>
		<touch site="right_foot" name="touch_right_foot"></touch>
		<touch site="left_foot" name="touch_left_foot"></touch>
		<jointpos joint="right_hip_x" name="jointpos_right_hip_x"></jointpos>
		<jointpos joint="right_hip_z" name="jointpos_right_hip_z"></jointpos>
		<jointpos joint="right_hip_y" name="jointpos_right_hip_y"></jointpos>
		<jointpos joint="right_leg_joint" name="jointpos_right_leg"></jointpos>
		<jointpos joint="right_foot_joint" name="jointpos_right_foot"></jointpos>
		<jointpos joint="left_hip_x" name="jointpos_left_hip_x"></jointpos>
		<jointpos joint="left_hip_z" name="jointpos_left_hip_z"></jointpos>
		<jointpos joint="left_hip_y" name="jointpos_left_hip_y"></jointpos>
		<jointpos joint="left_leg_joint" name="jointpos_left_leg"></jointpos>
		<jointpos joint="left_foot_joint" name="jointpos_left_foot"></jointpos>
		<jointvel joint="right_hip_x" name="jointvel_right_hip_x"></jointvel>
		<jointvel joint="right_hip_z" name="jointvel_right_hip_z"></jointvel>
		<jointvel joint="right_hip_y" name="jointvel_right_hip_y"></jointvel>
		<jointvel joint="right_leg_joint" name="jointvel_right_leg"></jointvel>
		<jointvel joint="right_foot_joint" name="jointvel_right_foot"></jointvel>
		<jointvel joint="left_hip_x" name="jointvel_left_hip_x"></jointvel>
		<jointvel joint="left_hip_z" name="jointvel_left_hip_z"></jointvel>
		<jointvel joint="left_hip_y" name="jointvel_left_hip_y"></jointvel>
		<jointvel joint="left_leg_joint" name="jointvel_left_leg"></jointvel>
		<jointvel joint="left_foot_joint" name="jointvel_left_foot"></jointvel>
		<accelerometer site="robot" name="accelerometer"></accelerometer>
		<velocimeter site="robot" name="velocimeter"></velocimeter>
		<gyro site="robot" name="gyro"></gyro>
		<magnetometer site="robot" name="magnetometer"></magnetometer>
		<subtreecom body="robot" name="subtreecom"></subtreecom>
		<subtreelinvel body="robot" name="subtreelinvel"></subtreelinvel>
		<subtreeangmom body="robot" name="subtreeangmom"></subtreeangmom>
	</sensor>
	<actuator>
		<motor ctrllimited="true" ctrlrange="-1.0 1.0" gear="10" joint="right_hip_x" name="right_hip_x"></motor>
		<motor ctrllimited="true" ctrlrange="-1.0 1.0" gear="10" joint="right_hip_z" name="right_hip_z"></motor>
		<motor ctrllimited="true" ctrlrange="-1.0 1.0" gear="30" joint="right_hip_y" name="right_hip_y"></motor>
		<motor ctrllimited="true" ctrlrange="-1.0 1.0" gear="30" joint="right_leg_joint"></motor>
		<motor ctrllimited="true" ctrlrange="-1.0 1.0" gear="40" joint="right_foot_joint"></motor>
		<motor ctrllimited="true" ctrlrange="-1.0 1.0" gear="10" joint="left_hip_x" name="left_hip_x"></motor>
		<motor ctrllimited="true" ctrlrange="-1.0 1.0" gear="10" joint="left_hip_z" name="left_hip_z"></motor>
		<motor ctrllimited="true" ctrlrange="-1.0 1.0" gear="30" joint="left_hip_y" name="left_hip_y"></motor>
		<motor ctrllimited="true" ctrlrange="-1.0 1.0" gear="30" joint="left_leg_joint"></motor>
		<motor ctrllimited="true" ctrlrange="-1.0 1.0" gear="40" joint="left_foot_joint"></motor>
	</actuator>
	<equality>
	</equality>
	<asset>
		<texture name="texplane" builtin="checker" height="100" width="100" rgb1="0.7 0.7 0.7" rgb2="0.8 0.8 0.8" type="2d"></texture>
		<texture type="skybox" builtin="gradient" rgb1="0.527 0.582 0.906" rgb2="0.1 0.1 0.35" width="800" height="800" markrgb="1 1 1" mark="random" random="0.001"></texture>
		<material name="MatPlane" reflectance="0.1" shininess="0.1" specular="0.1" texrepeat="10 10" texture="texplane"></material>
	</asset>
</mujoco>